<?xml version="1.0" ?>
<!-- =================================================================================== -->
<!-- |    This document was autogenerated by xacro from skeleton_v3.xacro              | -->
<!-- |    EDITING THIS FILE BY HAND IS NOT RECOMMENDED                                 | -->
<!-- =================================================================================== -->
<robot name="both_arm_baymax_skeleton">
  <link name="base_link">
    <visual>
      <origin rpy="0 0 0" xyz="0 0 0"/>
      <geometry>
        <box size="0.01 0.01 0.01"/>
      </geometry>
      <material name="invisible"/>
    </visual>
    <collision>
      <origin rpy="0 0 0" xyz="0 0 0"/>
      <geometry>
        <box size="0.01 0.01 0.01"/>
      </geometry>
    </collision>
    <inertial>
      <origin rpy="0 0 0" xyz="0 0 0"/>
      <mass value="0.001"/>
      <inertia ixx="1e-6" ixy="0" ixz="0" iyy="1e-6" iyz="0" izz="1e-6"/>
    </inertial>
  </link>
  <joint name="main_body_joint" type="fixed">
    <parent link="base_link"/>
    <child link="main_body"/>
    <origin rpy="0 0 0" xyz="0 0 0"/>
  </joint>
  <link name="main_body">
    <visual>
      <origin rpy="0 0 0" xyz="0 0 0"/>
      <geometry>
        <mesh filename="package://my_robot_bringup/description/meshes/skeleton_v3/new_main_body.stl" scale="0.001 0.001 0.001"/>
      </geometry>
      <material name="silver"/>
    </visual>
    <collision>
      <origin rpy="0 0 0" xyz="0 0 0"/>
      <geometry>
        <!-- <box size="0.5 0.5 0.5"/> -->
        <mesh filename="package://my_robot_bringup/description/meshes/skeleton_v3/main_body_collision.stl" scale="0.01 0.01 0.01"/>
      </geometry>
    </collision>
  </link>
  <!--RIGHT ARM-->
  <joint name="right_shoulder_pitch_joint" type="revolute">
    <parent link="main_body"/>
    <child link="right_shoulder_pitch"/>
    <origin rpy="0 0 0" xyz="0.0 -0.352 1.52"/>
    <axis xyz="0 -1 0"/>
    <!-- <limit lower="-0.69" upper="1.57" effort="100" velocity="10"/> -->
    <limit effort="100" lower="0.0" upper="1.57" velocity="10"/>
  </joint>
  <link name="right_shoulder_pitch">
    <visual>
      <origin rpy="0 0 0" xyz="0.0 0.0 0.0"/>
      <geometry>
        <mesh filename="package://my_robot_bringup/description/meshes/skeleton_v3/right_shoulder_pitch.stl"/>
      </geometry>
      <material name="silver"/>
    </visual>
    <collision>
      <origin rpy="0 0 0" xyz="0.0 0.0 0.0"/>
      <geometry>
        <box size="0.05 0.05 0.05"/>
      </geometry>
    </collision>
  </link>
  <joint name="right_shoulder_roll_joint" type="revolute">
    <parent link="right_shoulder_pitch"/>
    <child link="right_shoulder_roll"/>
    <origin rpy="0 0 0" xyz="0.0 -0.06 0.0"/>
    <axis xyz="-1 0 0"/>
    <limit effort="100" lower="0.0" upper="1.57" velocity="10"/>
    <!-- <limit lower="-1.57" upper="0.0" effort="100" velocity="10"/> -->
  </joint>
  <link name="right_shoulder_roll">
    <visual>
      <origin rpy="0 0 0" xyz="0.0 0.0 0.0"/>
      <geometry>
        <mesh filename="package://my_robot_bringup/description/meshes/skeleton_v3/right_shoulder_roll.stl"/>
      </geometry>
      <material name="silver"/>
    </visual>
    <collision>
      <origin rpy="0 0 0" xyz="0.0 0.0 0.0"/>
      <geometry>
        <box size="0.05 0.05 0.05"/>
      </geometry>
    </collision>
  </link>
  <joint name="right_shoulder_yaw_joint" type="revolute">
    <parent link="right_shoulder_roll"/>
    <child link="right_shoulder_yaw"/>
    <origin rpy="0 0 0" xyz="0.0 0.0 -0.0948"/>
    <axis xyz="0 0 -1"/>
    <limit effort="100" lower="-1.57" upper="0.80" velocity="10"/>
  </joint>
  <link name="right_shoulder_yaw">
    <visual>
      <origin rpy="0 0 0" xyz="0.0 0.0 0.0"/>
      <geometry>
        <mesh filename="package://my_robot_bringup/description/meshes/skeleton_v3/right_shoulder_yaw.stl"/>
      </geometry>
      <material name="silver"/>
    </visual>
    <collision>
      <origin rpy="0 0 0" xyz="0.0 0.0 0.0"/>
      <geometry>
        <box size="0.05 0.05 0.05"/>
      </geometry>
    </collision>
  </link>
  <joint name="right_elbow_joint" type="revolute">
    <parent link="right_shoulder_yaw"/>
    <child link="right_elbow"/>
    <origin rpy="0 0 0" xyz="0.0 0.0 -0.2971"/>
    <axis xyz="0 -1 0"/>
    <limit effort="100" lower="0.0" upper="1.57" velocity="10"/>
  </joint>
  <link name="right_elbow">
    <visual>
      <origin rpy="0 0 0" xyz="0.0 0.0 0.0"/>
      <geometry>
        <mesh filename="package://my_robot_bringup/description/meshes/skeleton_v3/right_elbow.stl"/>
      </geometry>
      <material name="silver"/>
    </visual>
    <collision>
      <origin rpy="0 0 0" xyz="0.0 0.0 -0.35"/>
      <geometry>
        <box size="0.05 0.05 0.05"/>
        <!-- <mesh filename="package://my_robot_bringup/description/meshes/skeleton_v3/right_elbow.stl" /> -->
      </geometry>
    </collision>
  </link>
  <!--LEFT ARM-->
  <joint name="left_shoulder_pitch_joint" type="revolute">
    <parent link="main_body"/>
    <child link="left_shoulder_pitch"/>
    <origin rpy="0 0 0" xyz="0.0 0.352 1.52"/>
    <axis xyz="0 1 0"/>
    <!-- <limit lower="-1.57" upper="0.69" effort="100" velocity="10"/> -->
    <limit effort="100" lower="-1.57" upper="0.0" velocity="10"/>
  </joint>
  <link name="left_shoulder_pitch">
    <visual>
      <origin rpy="0 0 0" xyz="0.0 0.0 0.0"/>
      <geometry>
        <mesh filename="package://my_robot_bringup/description/meshes/skeleton_v3/left_shoulder_pitch.stl"/>
      </geometry>
      <material name="silver"/>
    </visual>
    <collision>
      <origin rpy="0 0 0" xyz="0.0 0.0 0.0"/>
      <geometry>
        <box size="0.05 0.05 0.05"/>
      </geometry>
    </collision>
  </link>
  <joint name="left_shoulder_roll_joint" type="revolute">
    <parent link="left_shoulder_pitch"/>
    <child link="left_shoulder_roll"/>
    <origin rpy="0 0 0" xyz="0.0 0.06 0.0"/>
    <axis xyz="-1 0 0"/>
    <limit effort="100" lower="-1.57" upper="0.0" velocity="10"/>
    <!-- <limit lower="0.0" upper="1.57" effort="100" velocity="10"/> -->
  </joint>
  <link name="left_shoulder_roll">
    <visual>
      <origin rpy="0 0 0" xyz="0.0 0.0 0.0"/>
      <geometry>
        <mesh filename="package://my_robot_bringup/description/meshes/skeleton_v3/left_shoulder_roll.stl"/>
      </geometry>
      <material name="silver"/>
    </visual>
    <collision>
      <origin rpy="0 0 0" xyz="0.0 0.0 0.0"/>
      <geometry>
        <box size="0.05 0.05 0.05"/>
      </geometry>
    </collision>
  </link>
  <joint name="left_shoulder_yaw_joint" type="revolute">
    <parent link="left_shoulder_roll"/>
    <child link="left_shoulder_yaw"/>
    <origin rpy="0 0 0" xyz="0.0 0.0 -0.0948"/>
    <axis xyz="0 0 -1"/>
    <limit effort="100" lower="-0.80" upper="1.57" velocity="10"/>
  </joint>
  <link name="left_shoulder_yaw">
    <visual>
      <origin rpy="0 0 0" xyz="0.0 0.0 0.0"/>
      <geometry>
        <mesh filename="package://my_robot_bringup/description/meshes/skeleton_v3/left_shoulder_yaw.stl"/>
      </geometry>
      <material name="silver"/>
    </visual>
    <collision>
      <origin rpy="0 0 0" xyz="0.0 0.0 0.0"/>
      <geometry>
        <box size="0.05 0.05 0.05"/>
      </geometry>
    </collision>
  </link>
  <joint name="left_elbow_joint" type="revolute">
    <parent link="left_shoulder_yaw"/>
    <child link="left_elbow"/>
    <origin rpy="0 0 0" xyz="0.0 0.0 -0.2971"/>
    <axis xyz="0 1 0"/>
    <limit effort="100" lower="-1.57" upper="0.0" velocity="10"/>
  </joint>
  <link name="left_elbow">
    <visual>
      <origin rpy="0 0 0" xyz="0.0 0.0 0.0"/>
      <geometry>
        <mesh filename="package://my_robot_bringup/description/meshes/skeleton_v3/left_elbow.stl"/>
      </geometry>
      <material name="silver"/>
    </visual>
    <collision>
      <origin rpy="0 0 0" xyz="0.0 0.0 -0.35"/>
      <geometry>
        <box size="0.05 0.05 0.05"/>
      </geometry>
    </collision>
  </link>
</robot>
